Workbook

Sheet Master_Data
A1: Product Code | B1: Product Name | C1: Revision | D1: UoM | E1: Std Material Cost (Auto) | F1: Std Mfg Cost (Auto) Sub Con Charges | G1: Out source Job Work | H1: Std Labour Cost (Auto) | I1: Std Overhead (Auto) | J1: Std Total Cost (Auto) | K1: Target Margin % | L1: Target Selling Price (Auto) | M1: Last Updated
A2: DTH1500 | B2: DTH-1500 SQ BAR MAST ASSEMBLY | C2: R1 | D2: Nos | E2: =SUMIF(BOM_Costing!A:A,A2,BOM_Costing!I:I) -> 362204.16 | F2: =SUMIF('Mfg_Costing Sub-con'!A:A,A2,'Mfg_Costing Sub-con'!E:E) -> 3500 | H2: =SUMIF('Mfg_Costing Sub-con'!A:A,A2,'Mfg_Costing Sub-con'!F:F) -> 5000 | I2: =SUMIF('Mfg_Costing Sub-con'!A:A,A2,'Mfg_Costing Sub-con'!G:G) -> 4500 | J2: =SUM(E2:I2) -> 375204.16 | L2: =IFERROR(J2/(1-K2/100),"") -> 375204.16
A3: MA1010101019A0 | B3: DTH-1500 STANDERD-1 | C3: R1 | D3: Nos | E3: =SUMIF(BOM_Costing!A:A,A3,BOM_Costing!I:I) -> 1771424.4 | F3: =SUMIF('Mfg_Costing Sub-con'!A:A,A3,'Mfg_Costing Sub-con'!E:E) -> 168399.1 | G3: 76697 | H3: =SUMIF('Man &Machine Costing'!A:A,A3,'Man &Machine Costing'!E:E) -> 38040 | I3: =SUMIF('Man &Machine Costing'!A:A,A3,'Man &Machine Costing'!F:F) -> 10500 | J3: =SUM(E3:I3) -> 2065060.5 | L3: =IFERROR(J3/(1-K3/100),"") -> 2065060.5

Sheet BOM_Costing
A1: Product Code | B1: Item Code | C1: Item Description | D1: Category | E1: Qty | F1: UoM | G1: Unit Rate | H1: Raw Material | I1: Line Cost (Auto) | J1: Vendor | K1: Remarks
A2: DTH1500 | B2: 2020101042 | C2: Mast Structure KLR-1500 with Material | D2: Main Assembly | E2: 1500 | F2: Kg | G2: 108 | I2: =E2*G2 -> 162000 | K2: =1500/162000 -> 0.0092592593
A3: DTH1500 | B3: SA01100026A0 | C3: YOKE SCREW ASSEMBLY_SINGLE GROOVE | D3: Main Assembly | E3: 1 | F3: Nos | G3: 14318.39 | I3: 17361.84
A4: DTH1500 | B4: SA01100024A0 | C4: SMALL PULLEY ASSEMBLY_SINGLE GROOVE | D4: Main Assembly | E4: 2 | F4: Nos | G4: 14576.85 | I4: =E4*G4 -> 29153.7
A5: DTH1500 | B5: SA40000525A0 | C5: BOTTOM PULLEY ASSEMBLY_SINGLE GROOVE | D5: Main Assembly | E5: 1 | F5: Nos | G5: 13259.35 | I5: =E5*G5 -> 13259.35
A6: DTH1500 | B6: SA40000606A0 | C6: TRAVELING BLOCK ASSEMBLY_SINGLE GROOVE | D6: Main Assembly | E6: 1 | F6: Nos | G6: 38148.7 | I6: =E6*G6 -> 38148.7
A7: DTH1500 | B7: SA01100028A0 | C7: ROPE RETAINER ASSEMBLY | D7: Main Assembly | E7: 1 | F7: Nos | G7: 2131.19 | I7: =E7*G7 -> 2131.19
A8: DTH1500 | B8: 3025101010 | C8: Wire Rope 20mm Steel Core | D8: Raw Material | E8: 70 | F8: Mts | G8: 298.61 | I8: =E8*G8 -> 20902.7
A9: DTH1500 | B9: 3028201565 | C9: Wire Rope Clamp 20 MM | D9: Raw Material | E9: 12 | F9: Nos | G9: 78.18 | I9: =E9*G9 -> 938.16
A10: DTH1500 | B10: SA01100782A0 | C10: 140 FEED CYL BRACKET | D10: Main Assembly | E10: 1 | F10: Nos | G10: 840.1 | I10: =E10*G10 -> 840.1
A11: DTH1500 | B11: FC01100635A0 | C11: FEED 140 EYE PIECE,EN8 Ø126x258L 40pin | D11: Raw Material | E11: 1 | F11: Nos | G11: 2196.2 | I11: =E11*G11 -> 2196.2
A12: DTH1500 | B12: FC01100636A0 | C12: FEED140 CYL CAP EYE PIN,EN-19 Ø63X128L | D12: Raw Material | E12: 1 | F12: Nos | G12: 517.48 | I12: =E12*G12 -> 517.48
A13: DTH1500 | B13: FC40000081A0 | C13: EYE PIECE PIN _EN8_OD48X80L | D13: Main Assembly | E13: 1 | F13: Nos | G13: 145.06 | I13: =E13*G13 -> 145.06
A14: DTH1500 | B14: 3018101150 | C14: Feed 140 x 100 x 2350(250Bar)P4954 | D14: Raw Material | E14: 1 | F14: Nos | G14: 55500 | I14: =E14*G14 -> 55500
A15: DTH1500 | B15: SA40000565A0 | C15: MAST LOCKING ASSY (ON MAST) | D15: Main Assembly | E15: 2 | F15: Nos | G15: 215.07 | I15: =E15*G15 -> 430.14
... A17: DTH1500 | B17: SA03100266A0 | C17: H-PLATE ASSEMBLY | D17: Main Assembly | E17: 1 | F17: Nos | G17: 18649.32 | I17: =E17*G17 -> 18649.32
A19: MA1010101019A0 | B19: SA40001068A0 | C19: DTH-1500 SQ BAR MAST ASSEMBLY | E19: 1 | F19: Nos | G19: 322277.36 | I19: =E19*G19 -> 322277.36
A20: MA1010101019A0 | B20: SA40002822A0 | C20: PLATFORM 6.6METER MAIN ASSEMBLY (DTH-1500) | E20: 1 | F20: Nos | G20: 249651.62 | I20: =E20*G20 -> 249651.62
A21: MA1010101019A0 | B21: SA40002823A0 | C21: PTO & RH GEAR BOX MAIN ASSEMBLY (DTH-1500) | E21: 1 | F21: Nos | G21: 435076.06 | I21: =E21*G21 -> 435076.06
A22: MA1010101019A0 | B22: SA40002824A0 | C22: HYDRAULICS (DTH-1500) | E22: 1 | F22: Nos | G22: 117000 | I22: =E22*G22 -> 117000
A23: MA1010101019A0 | B23: SA40002825A0 | C23: ACCESSORIES (DTH-1500) | E23: 1 | F23: Nos | G23: 23274.01 | I23: =E23*G23 -> 23274.01
A24: MA1010101019A0 | B24: SA40002826A0 | C24: DTH-1500 [ BOC LIST ] | E24: 1 | F24: Nos | G24: 518804.68 | I24: =E24*G24 -> 518804.68
A25: MA1010101019A0 | B25: SA40002827A0 | C25: PAINTING LIST (DTH-1500) | E25: 1 | F25: Nos | G25: 59344.36 | I25: =E25*G25 -> 59344.36
A26: MA1010101019A0 | B26: SA40000520A0 | C26: ROD CHANGER ASSEMBLY | E26: 1 | F26: Nos | G26: 28375.6 | I26: =E26*G26 -> 28375.6
A27: MA1010101019A0 | B27: SA09100003A0 | C27: ONE TON WINCH GEAR BOX MTG ASSLY | E27: 1 | F27: Nos | G27: 17620.66 | I27: =E27*G27 -> 17620.66

Sheet Mfg_Costing  Sub-con
A1: Product Code | B1: Process | C1: Man& Machine/Hrs | D1: Rate per Hr | E1: Sub Con -Process Cost (Auto) | F1: Labour Cost | G1: Overhead Cost | H1: Remarks
A2: DTH1500 | B2: Cutting | C2: 8 | D2: 250 | E2: =C2*D2 -> 2000 | F2: 2500 | G2: 2000 | K2: =8*10*4 -> 320
A3: DTH1500 | B3: Assembly | C3: 10 | D3: 150 | E3: =C3*D3 -> 1500 | F3: 2500 | G3: 2500
A4: MA1010101019A0 | B4: CABIN WORK ( WITH MATERIAL) | H4: Angel Frame Work,In & Out GI Sheet Covering,Gas Welding Work,Cabin Painting Work,Main & Side Cabin Glass Fitting,Inside Tool Box Cushion Work & Inside Bed,Cabin Electrical Wiring Work,Including All Miscellaneous Materials, Fasteners & Consumables. | I4: 140000
A5: MA1010101019A0 | B5: Mast Comp. Work R 1500 Mast | E5: 30537.52
A6: MA1010101019A0 | B6: Bottom Guide Mounting | E6: 1442.66
A7: MA1010101019A0 | B7: Extra Base Guide Ribs | E7: 1346.2
A8: MA1010101019A0 | B8: Yoke Box Guard Top | E8: 672.04
A9: MA1010101019A0 | B9: Mast Resting Stand | E9: 769.56
A10: MA1010101019A0 | B10: BOW Cylinder Mounting | E10: 1002.76
A11: MA1010101019A0 | B11: Travelling Roller | E11: 627.52
A12: MA1010101019A0 | B12: Feed Cylinder Bracket | E12: 526.82
A13: MA1010101019A0 | B13: KLR Name Plate | E13: 395.38
A14: MA1010101019A0 | B14: MRC Mounting | E14: 969.9
A15: MA1010101019A0 | B15: H- Plate Roller | E15: 1578.34
A16: MA1010101019A0 | B16: Rod Changer Mounting | E16: 5000
... A21: MA1010101019A0 | B21: HYDRAULICS | E21: 34500
A22: MA1010101019A0 | B22: LEFT HAND STEARING CONVERSION | H22: Stearing open,Drilling & Fitting,Air Filter position changed,Clutch , Break , Excelator position changed,Hand Break position changed,Gear position changed ,Air pipe line position changed,Power Stearing position Changed | I22: 35000
A23: MA1010101019A0 | B23: Hyderalic Leaver Fitting | E23: 1800 | H23: R.N.T + Brazing,Air Tank Fitting
A24: MA1010101019A0 | B24: Rig Comp. & Chassis Painting Export Rig | E24: 12000
A25: MA1010101019A0 | B25: Water Washing Main Rig | E25: 1500
A26: MA1010101019A0 | B26: Hose Packing | E26: 1200
A27: MA1010101019A0 | B27: White Painting Single Coat Export Rig | E27: 800
A28: MA1010101019A0 | B28: Painting Rework | E28: 500
A29: MA1010101019A0 | B29: RH GEAR BOX FABRICATION | E29: 4000
A30: MA1010101019A0 | B30: Winch Gear Box | E30: 475

Sheet Man &Machine Costing
A1: Product Code | B1: Process | C1: Man& Machine/Hrs | D1: Rate per Hr | E1: Labour Cost | F1: Overhead Cost | G1: Remarks
A2: MA1010101019A0 | B2: Cutting | C2: 48 | D2: 480 | E2: =C2*D2 -> 23040 | F2: 5000
A3: MA1010101019A0 | B3: Assembly | C3: 60 | D3: 250 | E3: =C3*D3 -> 15000 | F3: 5500

Sheet Sheet2
A1: Process | B1: Man & Machine Hrs | C1: Rate/Hr (₹) | D1: Process Cost (₹) | E1: Labour Cost (₹) | F1: Overhead Cost (₹)
A2: Chassis Fabrication | B2: 120 | C2: 550 | D2: 66000 | E2: 35000 | F2: 12000
A3: Mast Fabrication | B3: 140 | C3: 600 | D3: 84000 | E3: 42000 | F3: 15000
A4: Rotary Head Assembly | B4: 80 | C4: 700 | D4: 56000 | E4: 28000 | F4: 10000
A5: Hydraulic Assembly | B5: 95 | C5: 500 | D5: 47500 | E5: 25000 | F5: 8000
A6: Engine Mounting | B6: 40 | C6: 500 | D6: 20000 | E6: 10000 | F6: 3500
A7: Compressor Mounting | B7: 45 | C7: 500 | D7: 22500 | E7: 11000 | F7: 4000
A8: PTO & Gear Box Assembly | B8: 55 | C8: 600 | D8: 33000 | E8: 15000 | F8: 5500
A9: Winch & Feed Assembly | B9: 60 | C9: 500 | D9: 30000 | E9: 14000 | F9: 5000
A10: Rod Changer Assembly | B10: 48 | C10: 500 | D10: 24000 | E10: 12000 | F10: 4000
A11: Cabin Fabrication | B11: 78 | C11: 680 | D11: 53100 | E11: 36500 | F11: Included
A12: Electrical Wiring | B12: 36 | C12: 450 | D12: 16200 | E12: 9000 | F12: 2500
A13: Pneumatic Line Fitting | B13: 32 | C13: 450 | D13: 14400 | E13: 8000 | F13: 2000
A14: Hydraulic Hose Routing | B14: 50 | C14: 500 | D14: 25000 | E14: 13000 | F14: 4500
A15: Painting & Surface Prep | B15: 60 | C15: 400 | D15: 24000 | E15: 12000 | F15: 4000
A16: Testing & Commissioning | B16: 40 | C16: 600 | D16: 24000 | E16: 10000 | F16: 5000
A17: Final Inspection & QC | B17: 24 | C17: 450 | D17: 10800 | E17: 6000 | F17: 2000
B18: =SUM(B2:B17) -> 1003

Sheet Missing BOM
B3: MAST METAL PIPES DTH-1500 | F3: DTH-1500 PAINTING LIST | J3: PILLER SIDES METAL PIPES
B4: SL NO | C4: MATERIAL DESCRIPTION | D4: QTY | F4: SL NO | G4: MATERIAL DESCRIPTION | H4: QTY | J4: S NO | K4: MATERIAL DESCRIPTIONS | L4: QTY
B5: 1 | C5: 30 0D Pipe 2200mm (Rotational Pipe) | D5: 2 | F5: 1 | G5: Orange | H5: 30ltr | J5: 1 | K5: 30 OD seamless pipe X 950L | L5: 4
B6: 2 | C6: 30 0D Pipe Bend 450mm (180 Degree) | D6: 2 | F6: 2 | G6: Milk White | H6: 6ltr | J6: 2 | K6: 22 OD ERW Pipe X 960L | L6: 1
B7: 3 | C7: 16 0D Pipe 2200mm (Leak Line) | D7: 1 | F7: 3 | G7: Red Oxide | H7: 12ltr | J7: 3 | K7: 16 OD seamless Pipe x 970L | L7: 1
B8: 4 | C8: 16 0D Pipe Bend 2200mm | D8: 1 | F8: 4 | G8: Ne Thinner | H8: 25ltr
B9: 5 | C9: 30 0D Feed Pipe 4900mm | D9: 1 | F9: 5 | G9: Carpant Oil | H9: 5ltr | J9: CLAMPS
B10: 6 | C10: 30 0D Feed Pipe 2500mm | D10: 1 | F10: 6 | G10: Bharath Paste | H10: 5Kg | J10: 1 | K10: 50x50xAnglex400L | L10: 2
B11: 7 | C11: 60 0D Feed Pipe 2220mm (ARW Pipe) | D11: 1 | F11: 7 | G11: Lappam | H11: 2Kg | J11: 2 | K11: 25X25 Sqbar 400L | L11: 4
B12: 8 | C12: 60 0D Feed Pipe Bend 300mm | D12: 1 | F12: 8 | G12: Black Enamil Paint | H12: 12ltr
B13: 9 | C13: 60 0D Feed Pipe Outside 300mm | D13: 1 | F13: 9 | G13: Pu Putty | J13: PILLER AIR LINE PIPE
B14: 10 | C14: 22mm OD 3000mm (ARW) | D14: 1 | F14: 10 | G14: Water Embri Paper 220 Grt | H14: 12 | J14: 1 | K14: 60 OD ERW Pipe x 350L | L14: 1
F15: 11 | G15: Meter paper 80 Grt | H15: 4m | J15: 2 | K15: 60 OD ERW Pipe x 280L | L15: 1
F16: 12 | G16: Hose Packing(Film) | H16: 2Kg | J16: 3 | K16: 60 OD ERW Pipe x 320L | L16: 1
J17: 4 | K17: Air line Nippal size seamless pipe x 60OD x 120 | L17: 1
B18: MAST METAL CLAMP-1500 | J18: 5 | K18: 6OD half Bend ERW outside | L18: 2
B19: SL NO | C19: MATERIAL DESCRIPTION | D19: QTY | J19: 6 | K19: Flange 150 x 60 OD hole | L19: 2
B20: 1 | C20: 12mm Plate 160*100 | D20: 3 | J20: 7 | K20: 1" Coupling | L20: 1
B21: 2 | C21: 12mm Plate 130*100 | D21: 3 | J21: 8 | K21: 1.5 " Coupling | L21: 1
B22: 3 | C22: 75*40 Channel 550L | D22: 2 | J22: 9 | K22: 0.5" Ball value | L22: 1
B23: 4 | C23: 75*40 Channel 180L | D23: 1 | J23: 10 | K23: 1" Ball value | L23: 1
B24: 5 | C24: 20*110*110 Plate | D24: 2 | J24: 11 | K24: 1.5" Ball value | L24: 1
B25: 6 | C25: 25*350*25 Square | D25: 4 | J25: 12 | K25: 2" Ball value spcl | L25: 1
B26: 7 | C26: 25*25*100 Square | D26: 1 | J26: 13 | K26: 0.5" Coupling | L26: 1
J28: UNDER THE PLATEFORM
J29: S NO | K29: MATERIAL DESCRIPTIONS | L29: QTY
J30: 1 | K30: 16 OD Seamless pipe x 5600mm | L30: 8
J32: CLAMPS
J33: S NO | K33: MATERIAL DESCRIPTIONS | L33: QTY
J34: 1 | K34: 16mm Thick x 380L | L34: 6
J35: 2 | K35: 35 x 35 x 130L | L35: 3
J37: SERIES PIPE
J38: S NO | K38: MATERIAL DESCRIPTIONS | L38: QTY
J39: 1 | K39: Seam less x OD16 x 100m | L39: 8
J40: 2 | K40: 16 x 16 x 380 L | L40: 4
J42: BOW
J43: S NO | K43: MATERIAL DESCRIPTIONS | L43: QTY
J44: 1 | K44: 16 OD x 900L | L44: 1
J45: 2 | K45: 16 OD x 800L | L45: 1
J46: CLAMPS
...

Sheet Cost_Summary
A1: Product Code | B1: Material Cost (Auto) | C1: Mfg Cost (Auto) | D1: Labour Cost (Auto) | E1: Overhead (Auto) | F1: Total Cost (Auto) | G1: Target Margin % | H1: Selling Price (Auto)
A2: DTH1500 | B2: =VLOOKUP(A2,Master_Data!A:L,5,FALSE) -> 362204.16 | C2: =VLOOKUP(A2,Master_Data!A:L,6,FALSE) -> 3500 | D2: =VLOOKUP(A2,Master_Data!A:L,7,FALSE) -> 0 | E2: =VLOOKUP(A2,Master_Data!A:L,8,FALSE) -> 5000 | F2: =VLOOKUP(A2,Master_Data!A:L,9,FALSE) -> 4500 | G2: =VLOOKUP(A2,Master_Data!A:L,10,FALSE) -> 375204.16 | H2: =VLOOKUP(A2,Master_Data!A:L,11,FALSE) -> 0
A3: MA1010101019A0 | B3: =VLOOKUP(A3,Master_Data!A:L,5,FALSE) -> 1771424.4 | C3: =VLOOKUP(A3,Master_Data!A:L,6,FALSE) -> 168399.1 | D3: =VLOOKUP(A3,Master_Data!A:L,7,FALSE) -> 76697 | E3: =VLOOKUP(A3,Master_Data!A:L,8,FALSE) -> 38040 | F3: =VLOOKUP(A3,Master_Data!A:L,9,FALSE) -> 10500 | G3: =VLOOKUP(A3,Master_Data!A:L,10,FALSE) -> 2065060.5 | H3: =VLOOKUP(A3,Master_Data!A:L,11,FALSE) -> 0

Sheet Variance_Analysis
A1: Month | B1: Product Code | C1: Standard Cost | D1: Actual Cost | E1: Variance (Auto) | F1: Variance % (Auto) | G1: Reason | H1: Action Plan | I1: Owner | J1: Status
A2: Apr-2026 | B2: DTH1500 | C2: 371704.16 | E2: =D2-C2 -> -371704.16 | F2: =IFERROR(E2/C2,"") -> -1
A3: Apr-2027 | B3: MA1010101019A0

Sheet Savings_Tracker
A1: Project/Initiative | B1: Product Code | C1: Old Cost | D1: New Cost | E1: Savings (Auto) | F1: Savings % (Auto) | G1: Start Date | H1: End Date | I1: Owner | J1: Status | K1: Remarks
A2: Vendor Renegotiation | B2: DTH1500 | C2: 469000 | D2: 580000 | E2: =C2-D2 -> -111000 | F2: =IFERROR(E2/C2,"") -> -0.23667377

Sheet T codes
B1: Material Master → BOM → Routing → Work Center | F1: Product Costing (CO-PC)
B2: ↓ | F2: CK11N, CK13N, CK24
B3: Standard Cost (CK11N / CK13N) | F3: BOM (Bill of Material)
B4: ↓ | F4: CS01, CS02, CS03
B5: Production Order (CO01) | F5: CS11, CS12, CS13, CS14, CS15
B6: ↓ | F6: Routing / Production
B7: Actual Cost Capture (Goods Issue, Confirmation) | F7: CA01, CA02, CA03
B8: ↓ | F8: COOIS, CO11N
B9: Variance Analysis (KKS2) | F9: Master Data / Procurement / Stock
B10: ↓ | F10: MM03, ME51N, ME2M, MMBE, MB51
B11: Settlement (KO88) | F11: KS01, KS02, KS03 (Cost Centers)
B12: ↓
B13: Profitability / Reports
B15: Area | C15: T-Code | D15: Purpose
B16: Material Master | C16: MM03 | D16: Price, valuation
B17: BOM | C17: CS03 | D17: Components & qty
B18: Routing | C18: CA03 | D18: Process steps
B19: Work Center | C19: CR03 | D19: Cost per hour
B20: Cost Center | C20: KS03 | D20: Cost allocation
B21: Activity Type | C21: KL03 | D21: Labour/machine cost
B23: B. Costing (Core Area) | C23: CK11N | D23: Create cost estimate
C24: CK13N | D24: Display cost
C25: CK40N | D25: Mass costing
C26: CK24 | D26: Release standard cost
B27: C. Cost Component & Structure (Deep Understanding) | C27: CK13N → Cost Component View | D27: Material / labour / overhead split
C28: OKTZ | D28: Cost component structure
C29: OKKN | D29: Costing variant
B31: D. Production Order (Actual Cost Flow) | C31: CO01 | D31: Create production order
C32: CO02 | D32: Change order
C33: CO03 | D33: Display order
B35: E. Actual Cost Capture | C35: MB1A / MIGO | D35: Material issue
C36: MB1B | D36: Transfer posting
C37: CO11N | D37: Production confirmation
C38: KB31N | D38: Activity posting
B40: F. Variance & Analysis (VERY IMPORTANT FOR YOU) | C40: KKS2 | D40: Variance calculation
C41: KKS1 | D41: Variance (single order)
C42: KKBC_HOE | D42: Cost analysis report
C43: COOIS | D43: Order info system
B45: G. Settlement | C45: KO88 | D45: Settle production order
B47: H. Reporting & Profitability | C47: S_ALR_87013127 | D47: Cost center report
...

Sheet DTH1500_Management_View
A1: FG Code | B1: Product | C1: Assembly | D1: Category | E1: Vendor | F1: Estimated Cost | G1: Selling Price | H1: Margin | I1: Margin % | J1: Remarks
A2: MA1010101007A0 | B2: DTH 1500 | C2: Mast Assembly | D2: Fabrication | E2: Internal | F2: 359019 | G2: 450000 | H2: =G2-F2 -> 90981 | I2: =H2/G2 -> 0.20218 | J2: Critical Assembly
A3: MA1010101007A0 | B3: DTH 1500 | C3: Hydraulic | D3: BOC | E3: Danfoss | F3: 285000 | G3: 360000 | H3: =G3-F3 -> 75000 | I3: =H3/G3 -> 0.20833333 | J3: Hydraulic Package
A4: MA1010101007A0 | B4: DTH 1500 | C4: Platform | D4: Subcontract | E4: Platform Vendor | F4: 175000 | G4: 230000 | H4: =G4-F4 -> 55000 | I4: =H4/G4 -> 0.23913043 | J4: Fabrication Cost
A5: MA1010101007A0 | B5: DTH 1500 | C5: Painting | D5: Subcontract | E5: Painter Vendor | F5: 15000 | G5: 25000 | H5: =G5-F5 -> 10000 | I5: =H5/G5 -> 0.4 | J5: Final Finish

Sheet Costing_Workflow
A1: DTH1500 Product Costing Workflow
A3: 1. Extract BOM from SAP CS12
A4: 2. Validate Parent-Child structure
A5: 3. Verify Routing in CA03
A6: 4. Validate RM & BOC prices with Procurement
A7: 5. Add subcontracting bills
A8: 6. Run CK11N costing
A9: 7. Analyze CK13N cost structure
A10: 8. Validate inventory physically
A11: 9. Release standard price in CK24
A12: 10. Review margins before quotation release

Sheet KPI_Dashboard
A1: KPI | B1: Target | C1: Actual | D1: Status
A2: Margin % | B2: 20% | C2: 18% | D2: Monitor
A3: Inventory Accuracy | B3: 98% | C3: 95% | D3: Improve
A4: Open PO Aging | B4: <30 Days | C4: 45 Days | D4: Action Required
A5: Cost Variance | B5: <5% | C5: 8% | D5: Review
A6: SAP Update Compliance | B6: 100% | C6: 90% | D6: Improve
